<robot xmlns:xacro="http://www.ros.org/wiki/xacro">

  <!-- ================== WHEELS ================== -->

  <!-- Rear Left Wheel (DRIVEN) -->
  <link name="rear_left_wheel">
    <visual>
      <geometry>
        <cylinder radius="0.10" length="0.05"/>
      </geometry>
      <origin rpy="1.5708 0 0"/>
    </visual>
    <collision>
      <geometry>
        <cylinder radius="0.10" length="0.05"/>
      </geometry>
      <origin rpy="1.5708 0 0"/>      
    </collision>

    <xacro:cylinder_inertial mass="2" r="0.10" h="0.05"/>
  </link>

  <joint name="rear_left_wheel_joint" type="continuous">
    <parent link="base_link"/>
    <child link="rear_left_wheel"/>
    <origin xyz="-0.20 0.22 0.05" rpy="0 0 0"/>
    <axis xyz="0 1 0"/>
  </joint>

  <!-- Rear Right Wheel (DRIVEN) -->
  <link name="rear_right_wheel">
    <visual>
      <geometry>
        <cylinder radius="0.10" length="0.05"/>
      </geometry>
      <origin rpy="1.5708 0 0"/>
    </visual>

    <collision>
      <geometry>
        <cylinder radius="0.10" length="0.05"/>
      </geometry>
      <origin rpy="1.5708 0 0"/>      
    </collision>

    <xacro:cylinder_inertial mass="2" r="0.10" h="0.05"/>
  </link>

  <joint name="rear_right_wheel_joint" type="continuous">
    <parent link="base_link"/>
    <child link="rear_right_wheel"/>
    <origin xyz="-0.20 -0.22 0.05"  rpy="0 0 0"/>
    <axis xyz="0 1 0"/>
  </joint>




  <!-- Passive Casters -->


  <!-- Front Left Caster -->
  <link name="front_left_wheel">
    <visual>
      <geometry>
        <cylinder radius="0.1" length="0.05"/>
      </geometry>
      <origin rpy="1.5708 0 0"/>
    </visual>
    <collision>
      <geometry>
        <cylinder radius="0.1" length="0.05"/>
      </geometry>
      <origin rpy="1.5708 0 0"/>      
    </collision>

    <xacro:cylinder_inertial mass="2" r="0.1" h="0.05"/>
  </link>

  <joint name="front_left_wheel_joint" type="fixed">
    <parent link="base_link"/>
    <child link="front_left_wheel"/>
    <origin xyz="0.20 0.22 0.05" rpy="0 0 0"/>
    <axis xyz="0 1 0"/>
  </joint>

  <!-- Front Right Caster -->
  <link name="front_right_wheel">
    <visual>
      <geometry>
        <cylinder radius="0.1" length="0.05"/>
      </geometry>
      <origin rpy="1.5708 0 0"/>
    </visual>
    <collision>
      <geometry>
        <cylinder radius="0.1" length="0.05"/>
      </geometry>
      <origin rpy="1.5708 0 0"/>      
    </collision>

    <xacro:cylinder_inertial mass="2" r="0.1" h="0.05"/>
  </link>

  <joint name="front_right_wheel_joint" type="fixed">
    <parent link="base_link"/>
    <child link="front_right_wheel"/>
    <origin xyz="0.20 -0.22 0.05" rpy="0 0 0"/>
    <axis xyz="0 1 0"/>
  </joint>
</robot>